test_stimulus/nsdaq_itch50_08302019_0.txt
S 0 0 11046036981912 O
R 14 0 11316046568183 AAPL
R 339 0 11316059936969 AMD
R 389 0 11316061686253 AMZN
R 1635 0 11316093790700 COST
R 2731 0 11316118177636 FB
R 3448 0 11316133653951 GOOG
R 4173 0 11316149072417 INTC
R 4480 0 11316155922445 JPM
R 5277 0 11316172769291 MSFT
R 5487 0 11316177424218 NFLX
R 5695 0 11316182008965 NVDA
R 7922 0 11316229591151 TSLA
S 0 0 14400000191772 S
S 0 0 34200000081775 Q
A 7922 0 34200000557033 11222404 S 100 TSLA 2321900
A 7922 0 34200000944762 11222432 B 100 TSLA 2271100
D 7922 0 34200001201078 9573336
D 339 0 34200001452372 5764565
D 339 0 34200001765560 5764569
F 339 0 34200001774045 7940409 B 100 AMD 229300 SBSH
F 339 0 34200002254808 7940637 S 100 AMD 404700 SBSH
A 4480 0 34200002509113 5841798 S 100 JPM 1100000
D 5277 0 34200003100568 7542903
A 5695 0 34200003111669 7549859 B 100 NVDA 1686800
A 5695 0 34200003113557 7549863 B 100 NVDA 1686800
A 5695 0 34200003208282 7549931 S 100 NVDA 1706100
A 5695 0 34200003223306 7549939 B 100 NVDA 1670000
A 5695 0 34200003453380 7550187 S 100 NVDA 1708900
A 5695 0 34200003456737 7550191 B 100 NVDA 1668500
D 5695 0 34200004634436 7550191
A 5695 0 34200004642787 7551063 B 100 NVDA 1666600
A 3448 0 34200004903258 5843562 B 200 GOOG 11967500
D 5695 0 34200005188580 7551063
A 5695 0 34200005195996 7551579 B 100 NVDA 1661200
F 3448 0 34200005492958 5843886 S 100 GOOG 14379000 UBSS
F 3448 0 34200005497313 5843898 B 100 GOOG 9579500 UBSS
A 389 0 34200005617902 7943809 S 12 AMZN 17987600
A 389 0 34200005654676 7943849 S 100 AMZN 18167400
A 389 0 34200005660861 7943857 B 100 AMZN 17768700
D 5277 0 34200005824034 7542531
F 7922 0 34200005973002 11226524 B 100 TSLA 1835200 UBSS
F 5487 0 34200006021945 7552351 B 100 NFLX 2390700 UBSS
F 7922 0 34200006044347 11226600 S 100 TSLA 2757400 UBSS
A 5695 0 34200006045416 7552375 B 100 NVDA 1653000
F 5487 0 34200006186585 7552455 S 100 NFLX 3587600 UBSS
A 5695 0 34200006543543 7552719 B 100 NVDA 1653000
A 5695 0 34200006554002 7552739 S 100 NVDA 1722400
X 339 0 34200006643660 6655953 241
A 3448 0 34200006684127 5844522 S 20 GOOG 12002500
F 5695 0 34200006693080 7552835 S 100 NVDA 1773100 CTDL
A 3448 0 34200006705977 5844582 S 100 GOOG 12005900
F 5695 0 34200006804371 7552919 B 100 NVDA 1602400 CTDL
A 5695 0 34200006851016 7552983 S 100 NVDA 1722400
A 5277 0 34200007132495 7553259 S 200 MSFT 1392400
A 5277 0 34200007173998 7553307 S 100 MSFT 1406300
A 5277 0 34200007178535 7553311 B 100 MSFT 1377600
F 5487 0 34200007442203 7553503 B 100 NFLX 2510200 CDRG
F 5487 0 34200007457764 7553523 S 100 NFLX 3468000 CDRG
A 5695 0 34200007859725 7554007 S 100 NVDA 1688500
D 7922 0 34200008461959 8988356
F 5695 0 34200008617703 7554727 B 100 NVDA 1602400 CDRG
F 5695 0 34200008626373 7554747 S 100 NVDA 1773100 CDRG
D 7922 0 34200008820300 8988360
F 7922 0 34200009036255 11229980 B 100 TSLA 1674600 SBSH
U 14 0 34200009297023 7726541 7947157 100 2116000
F 7922 0 34200009474150 11230468 S 100 TSLA 2918300 SBSH
U 389 0 34200009546186 7931853 7947473 100 18527600
F 5277 0 34200011407243 7557491 B 100 MSFT 1168900 CDRG
F 5277 0 34200011509964 7557599 S 100 MSFT 1614700 CDRG
A 3448 0 34200012291428 5850398 S 10 GOOG 11999500
F 5695 0 34200013637124 7559447 B 100 NVDA 1416900 CDRG
F 5695 0 34200013789868 7559611 S 100 NVDA 1958800 CDRG
A 14 0 34200013883023 7951285 S 100 AAPL 2122700
A 14 0 34200013885453 7951289 B 100 AAPL 2078400
A 339 0 34200013897622 7951325 B 100 AMD 316000
A 4173 0 34200015179670 5852986 S 100 INTC 474300
U 5695 0 34200017132086 7479727 7563695 100 1740400
U 5695 0 34200017162913 7489787 7563723 100 1636500
D 5277 0 34200018039873 7553259
A 5277 0 34200018534110 7565199 S 200 MSFT 1392600
F 14 0 34200019027721 7956217 B 100 AAPL 1764300 CDRG
F 14 0 34200019050025 7956245 S 100 AAPL 2437900 CDRG
F 339 0 34200019533907 7956685 B 100 AMD 265500 CDRG
F 339 0 34200019553962 7956705 S 100 AMD 366500 CDRG
U 5277 0 34200019877006 7541907 7566407 100 1433800
U 5277 0 34200019912823 7540791 7566463 100 1349700
D 5277 0 34200020193574 7565199
A 5277 0 34200020752192 7567335 S 200 MSFT 1392800
A 4173 0 34200021469395 5859486 S 100 INTC 479600
A 4173 0 34200021475758 5859494 B 100 INTC 464100
D 5277 0 34200023066241 7567335
A 5277 0 34200023489431 7569759 S 200 MSFT 1392500
A 3448 0 34200025221891 5863130 S 10 GOOG 11999600
D 4173 0 34200026278622 5852986
A 4173 0 34200026336552 5864242 S 100 INTC 473900
A 4173 0 34200026370283 5864270 S 100 INTC 478600
A 4173 0 34200026372818 5864274 B 100 INTC 468100
D 4480 0 34200027812850 49486
D 4480 0 34200028254723 49386
A 389 0 34200029193920 7964365 B 100 AMZN 17773000
A 389 0 34200029196124 7964369 S 100 AMZN 18154700
D 389 0 34200029237644 7938889
F 389 0 34200029348212 7964413 B 100 AMZN 15082300 CDRG
F 389 0 34200029368295 7964429 S 100 AMZN 20865900 CDRG
D 389 0 34200029401846 7964365
A 389 0 34200029410425 7964441 B 100 AMZN 17795300
U 389 0 34200030459653 7888173 7965089 100 17435700
D 389 0 34200030533097 7964441
A 389 0 34200030538948 7965145 B 100 AMZN 17784100
D 389 0 34200030608285 7965145
A 389 0 34200030612884 7965221 B 100 AMZN 17773000
A 3448 0 34200030643662 5867674 B 23 GOOG 11978500
A 389 0 34200031224949 7965349 B 100 AMZN 17941100
A 4173 0 34200031494817 5868198 S 100 INTC 474300
U 3448 0 34200031639344 5835630 5868350 1 11978600
A 4173 0 34200032566908 5869010 B 100 INTC 463200
F 4173 0 34200032570750 5869018 B 100 INTC 449000 CTDL
A 4173 0 34200032585918 5869038 S 100 INTC 482200
F 4173 0 34200032587058 5869042 S 100 INTC 496400 CTDL
A 4173 0 34200033280791 5869698 B 100 INTC 463200
A 4173 0 34200033283220 5869710 S 100 INTC 482200
D 4173 0 34200034054111 5834090
F 4173 0 34200034335494 5870850 B 100 INTC 449000 CDRG
F 4173 0 34200034351507 5870854 S 100 INTC 496400 CDRG
F 4173 0 34200034422397 5870882 B 100 INTC 397000 CDRG
F 4173 0 34200034477163 5870902 S 100 INTC 548400 CDRG
U 5695 0 34200034559725 7563695 7575963 100 1739200
D 5695 0 34200036608293 7549859
D 5695 0 34200037365761 7549863
D 5695 0 34200037431121 7549939
A 5695 0 34200037433605 7578591 B 100 NVDA 1665500
F 389 0 34200039915218 7969521 B 100 AMZN 17057400 CTDL
A 389 0 34200039923886 7969529 B 100 AMZN 17596000
A 389 0 34200039935632 7969537 S 100 AMZN 18341600
F 389 0 34200039937136 7969541 S 100 AMZN 18881100 CTDL
U 5695 0 34200040278877 7563723 7580063 100 1636000
F 389 0 34200040359590 7969713 B 100 AMZN 17057400 CDRG
F 389 0 34200040366518 7969717 S 100 AMZN 18881100 CDRG
A 389 0 34200040599135 7969789 B 100 AMZN 17596000
A 389 0 34200040618401 7969793 S 100 AMZN 18341600
U 5277 0 34200042382475 7566407 7581223 100 1434300
F 5277 0 34200042642644 7581427 S 800 MSFT 1446600 GSCO
F 5277 0 34200042650285 7581435 B 800 MSFT 1336000 GSCO
A 5277 0 34200043416311 7581879 S 100 MSFT 1413500
A 5277 0 34200043418658 7581883 B 100 MSFT 1367500
F 2731 0 34200044932545 5878622 B 600 FB 1793500 GSCO
D 389 0 34200045645629 7965349
A 5277 0 34200047866807 7584811 S 100 MSFT 1392000
D 5277 0 34200049048811 7581879
A 5277 0 34200049057747 7585327 S 100 MSFT 1409100
A 389 0 34200050257454 7974541 B 136 AMZN 17981900
A 389 0 34200050306917 7974553 B 100 AMZN 17802100
D 389 0 34200050311844 7943857
D 389 0 34200052527858 7965221
A 389 0 34200052542525 7975625 B 100 AMZN 17788100
C 389 2 34200054029842 7974541 136 52376 Y 17982000
D 389 0 34200054067066 7974553
A 389 0 34200054073266 7976241 B 100 AMZN 17768700
A 14 0 34200055132751 7976681 B 100 AAPL 2100300
D 4173 0 34200057092042 5608178
A 7922 0 34200057152368 11260232 B 30 TSLA 2280000
D 5277 0 34200057311200 7335007
D 5277 0 34200057312485 7335011
A 3448 0 34200059692512 5884970 S 7 GOOG 11998700
F 14 0 34200061618043 7979589 B 100 AAPL 1974300 SGAS
F 14 0 34200061820505 7979725 S 100 AAPL 2227800 SGAS
F 4173 0 34200062635725 5885842 B 100 INTC 444200 SGAS
F 4173 0 34200062661247 5885854 S 100 INTC 501100 SGAS
F 4480 0 34200062725084 5885866 B 100 JPM 1031800 SGAS
A 389 0 34200062821162 7980449 S 5 AMZN 17989900
F 4480 0 34200062917315 5885914 S 100 JPM 1164700 SGAS
F 5277 0 34200063292793 7591079 B 100 MSFT 1308000 SGAS
